[2024-02-02T17:07:20.029+0000] {processor.py:161} INFO - Started process (PID=32) to work on /opt/airflow/dags/sf311_data_upload_dag.py
[2024-02-02T17:07:20.031+0000] {processor.py:830} INFO - Processing file /opt/airflow/dags/sf311_data_upload_dag.py for tasks to queue
[2024-02-02T17:07:20.036+0000] {logging_mixin.py:188} INFO - [2024-02-02T17:07:20.036+0000] {dagbag.py:538} INFO - Filling up the DagBag from /opt/airflow/dags/sf311_data_upload_dag.py
[2024-02-02T17:07:20.103+0000] {logging_mixin.py:188} INFO - [2024-02-02T17:07:20.099+0000] {dagbag.py:348} ERROR - Failed to import: /opt/airflow/dags/sf311_data_upload_dag.py
Traceback (most recent call last):
  File "/home/airflow/.local/lib/python3.8/site-packages/airflow/models/dagbag.py", line 344, in parse
    loader.exec_module(new_module)
  File "<frozen importlib._bootstrap_external>", line 843, in exec_module
  File "<frozen importlib._bootstrap>", line 219, in _call_with_frames_removed
  File "/opt/airflow/dags/sf311_data_upload_dag.py", line 5, in <module>
    from airflow import PythonOperator
ImportError: cannot import name 'PythonOperator' from 'airflow' (/home/airflow/.local/lib/python3.8/site-packages/airflow/__init__.py)
[2024-02-02T17:07:20.108+0000] {processor.py:842} WARNING - No viable dags retrieved from /opt/airflow/dags/sf311_data_upload_dag.py
[2024-02-02T17:07:20.169+0000] {processor.py:183} INFO - Processing /opt/airflow/dags/sf311_data_upload_dag.py took 0.143 seconds
[2024-02-02T17:07:51.158+0000] {processor.py:161} INFO - Started process (PID=88) to work on /opt/airflow/dags/sf311_data_upload_dag.py
[2024-02-02T17:07:51.165+0000] {processor.py:830} INFO - Processing file /opt/airflow/dags/sf311_data_upload_dag.py for tasks to queue
[2024-02-02T17:07:51.180+0000] {logging_mixin.py:188} INFO - [2024-02-02T17:07:51.180+0000] {dagbag.py:538} INFO - Filling up the DagBag from /opt/airflow/dags/sf311_data_upload_dag.py
[2024-02-02T17:07:51.201+0000] {logging_mixin.py:188} INFO - [2024-02-02T17:07:51.197+0000] {dagbag.py:348} ERROR - Failed to import: /opt/airflow/dags/sf311_data_upload_dag.py
Traceback (most recent call last):
  File "/home/airflow/.local/lib/python3.8/site-packages/airflow/models/dagbag.py", line 344, in parse
    loader.exec_module(new_module)
  File "<frozen importlib._bootstrap_external>", line 843, in exec_module
  File "<frozen importlib._bootstrap>", line 219, in _call_with_frames_removed
  File "/opt/airflow/dags/sf311_data_upload_dag.py", line 5, in <module>
    from airflow import PythonOperator
ImportError: cannot import name 'PythonOperator' from 'airflow' (/home/airflow/.local/lib/python3.8/site-packages/airflow/__init__.py)
[2024-02-02T17:07:51.203+0000] {processor.py:842} WARNING - No viable dags retrieved from /opt/airflow/dags/sf311_data_upload_dag.py
[2024-02-02T17:07:51.225+0000] {processor.py:183} INFO - Processing /opt/airflow/dags/sf311_data_upload_dag.py took 0.074 seconds
[2024-02-02T17:08:22.050+0000] {processor.py:161} INFO - Started process (PID=143) to work on /opt/airflow/dags/sf311_data_upload_dag.py
[2024-02-02T17:08:22.054+0000] {processor.py:830} INFO - Processing file /opt/airflow/dags/sf311_data_upload_dag.py for tasks to queue
[2024-02-02T17:08:22.059+0000] {logging_mixin.py:188} INFO - [2024-02-02T17:08:22.058+0000] {dagbag.py:538} INFO - Filling up the DagBag from /opt/airflow/dags/sf311_data_upload_dag.py
[2024-02-02T17:08:22.076+0000] {logging_mixin.py:188} INFO - [2024-02-02T17:08:22.074+0000] {dagbag.py:348} ERROR - Failed to import: /opt/airflow/dags/sf311_data_upload_dag.py
Traceback (most recent call last):
  File "/home/airflow/.local/lib/python3.8/site-packages/airflow/models/dagbag.py", line 344, in parse
    loader.exec_module(new_module)
  File "<frozen importlib._bootstrap_external>", line 843, in exec_module
  File "<frozen importlib._bootstrap>", line 219, in _call_with_frames_removed
  File "/opt/airflow/dags/sf311_data_upload_dag.py", line 5, in <module>
    from airflow import PythonOperator
ImportError: cannot import name 'PythonOperator' from 'airflow' (/home/airflow/.local/lib/python3.8/site-packages/airflow/__init__.py)
[2024-02-02T17:08:22.078+0000] {processor.py:842} WARNING - No viable dags retrieved from /opt/airflow/dags/sf311_data_upload_dag.py
[2024-02-02T17:08:22.097+0000] {processor.py:183} INFO - Processing /opt/airflow/dags/sf311_data_upload_dag.py took 0.054 seconds
[2024-02-02T17:09:29.795+0000] {processor.py:161} INFO - Started process (PID=31) to work on /opt/airflow/dags/sf311_data_upload_dag.py
[2024-02-02T17:09:29.798+0000] {processor.py:830} INFO - Processing file /opt/airflow/dags/sf311_data_upload_dag.py for tasks to queue
[2024-02-02T17:09:29.802+0000] {logging_mixin.py:188} INFO - [2024-02-02T17:09:29.801+0000] {dagbag.py:538} INFO - Filling up the DagBag from /opt/airflow/dags/sf311_data_upload_dag.py
[2024-02-02T17:09:29.825+0000] {logging_mixin.py:188} INFO - [2024-02-02T17:09:29.819+0000] {dagbag.py:348} ERROR - Failed to import: /opt/airflow/dags/sf311_data_upload_dag.py
Traceback (most recent call last):
  File "/home/airflow/.local/lib/python3.8/site-packages/airflow/models/dagbag.py", line 344, in parse
    loader.exec_module(new_module)
  File "<frozen importlib._bootstrap_external>", line 843, in exec_module
  File "<frozen importlib._bootstrap>", line 219, in _call_with_frames_removed
  File "/opt/airflow/dags/sf311_data_upload_dag.py", line 5, in <module>
    from airflow import PythonOperator
ImportError: cannot import name 'PythonOperator' from 'airflow' (/home/airflow/.local/lib/python3.8/site-packages/airflow/__init__.py)
[2024-02-02T17:09:29.828+0000] {processor.py:842} WARNING - No viable dags retrieved from /opt/airflow/dags/sf311_data_upload_dag.py
[2024-02-02T17:09:29.848+0000] {processor.py:183} INFO - Processing /opt/airflow/dags/sf311_data_upload_dag.py took 0.057 seconds
[2024-02-02T17:10:00.133+0000] {processor.py:161} INFO - Started process (PID=38) to work on /opt/airflow/dags/sf311_data_upload_dag.py
[2024-02-02T17:10:00.138+0000] {processor.py:830} INFO - Processing file /opt/airflow/dags/sf311_data_upload_dag.py for tasks to queue
[2024-02-02T17:10:00.145+0000] {logging_mixin.py:188} INFO - [2024-02-02T17:10:00.145+0000] {dagbag.py:538} INFO - Filling up the DagBag from /opt/airflow/dags/sf311_data_upload_dag.py
[2024-02-02T17:10:00.156+0000] {logging_mixin.py:188} INFO - [2024-02-02T17:10:00.154+0000] {dagbag.py:348} ERROR - Failed to import: /opt/airflow/dags/sf311_data_upload_dag.py
Traceback (most recent call last):
  File "/home/airflow/.local/lib/python3.8/site-packages/airflow/models/dagbag.py", line 344, in parse
    loader.exec_module(new_module)
  File "<frozen importlib._bootstrap_external>", line 843, in exec_module
  File "<frozen importlib._bootstrap>", line 219, in _call_with_frames_removed
  File "/opt/airflow/dags/sf311_data_upload_dag.py", line 5, in <module>
    from airflow import PythonOperator
ImportError: cannot import name 'PythonOperator' from 'airflow' (/home/airflow/.local/lib/python3.8/site-packages/airflow/__init__.py)
[2024-02-02T17:10:00.158+0000] {processor.py:842} WARNING - No viable dags retrieved from /opt/airflow/dags/sf311_data_upload_dag.py
[2024-02-02T17:10:00.176+0000] {processor.py:183} INFO - Processing /opt/airflow/dags/sf311_data_upload_dag.py took 0.049 seconds
[2024-02-02T17:10:30.495+0000] {processor.py:161} INFO - Started process (PID=46) to work on /opt/airflow/dags/sf311_data_upload_dag.py
[2024-02-02T17:10:30.498+0000] {processor.py:830} INFO - Processing file /opt/airflow/dags/sf311_data_upload_dag.py for tasks to queue
[2024-02-02T17:10:30.501+0000] {logging_mixin.py:188} INFO - [2024-02-02T17:10:30.501+0000] {dagbag.py:538} INFO - Filling up the DagBag from /opt/airflow/dags/sf311_data_upload_dag.py
[2024-02-02T17:10:30.513+0000] {logging_mixin.py:188} INFO - [2024-02-02T17:10:30.510+0000] {dagbag.py:348} ERROR - Failed to import: /opt/airflow/dags/sf311_data_upload_dag.py
Traceback (most recent call last):
  File "/home/airflow/.local/lib/python3.8/site-packages/airflow/models/dagbag.py", line 344, in parse
    loader.exec_module(new_module)
  File "<frozen importlib._bootstrap_external>", line 843, in exec_module
  File "<frozen importlib._bootstrap>", line 219, in _call_with_frames_removed
  File "/opt/airflow/dags/sf311_data_upload_dag.py", line 5, in <module>
    from airflow import PythonOperator
ImportError: cannot import name 'PythonOperator' from 'airflow' (/home/airflow/.local/lib/python3.8/site-packages/airflow/__init__.py)
[2024-02-02T17:10:30.516+0000] {processor.py:842} WARNING - No viable dags retrieved from /opt/airflow/dags/sf311_data_upload_dag.py
[2024-02-02T17:10:30.533+0000] {processor.py:183} INFO - Processing /opt/airflow/dags/sf311_data_upload_dag.py took 0.042 seconds
[2024-02-02T17:11:00.785+0000] {processor.py:161} INFO - Started process (PID=53) to work on /opt/airflow/dags/sf311_data_upload_dag.py
[2024-02-02T17:11:00.788+0000] {processor.py:830} INFO - Processing file /opt/airflow/dags/sf311_data_upload_dag.py for tasks to queue
[2024-02-02T17:11:00.794+0000] {logging_mixin.py:188} INFO - [2024-02-02T17:11:00.793+0000] {dagbag.py:538} INFO - Filling up the DagBag from /opt/airflow/dags/sf311_data_upload_dag.py
[2024-02-02T17:11:00.810+0000] {logging_mixin.py:188} INFO - [2024-02-02T17:11:00.807+0000] {dagbag.py:348} ERROR - Failed to import: /opt/airflow/dags/sf311_data_upload_dag.py
Traceback (most recent call last):
  File "/home/airflow/.local/lib/python3.8/site-packages/airflow/models/dagbag.py", line 344, in parse
    loader.exec_module(new_module)
  File "<frozen importlib._bootstrap_external>", line 843, in exec_module
  File "<frozen importlib._bootstrap>", line 219, in _call_with_frames_removed
  File "/opt/airflow/dags/sf311_data_upload_dag.py", line 5, in <module>
    from airflow import PythonOperator
ImportError: cannot import name 'PythonOperator' from 'airflow' (/home/airflow/.local/lib/python3.8/site-packages/airflow/__init__.py)
[2024-02-02T17:11:00.813+0000] {processor.py:842} WARNING - No viable dags retrieved from /opt/airflow/dags/sf311_data_upload_dag.py
[2024-02-02T17:11:00.846+0000] {processor.py:183} INFO - Processing /opt/airflow/dags/sf311_data_upload_dag.py took 0.077 seconds
[2024-02-02T17:11:31.049+0000] {processor.py:161} INFO - Started process (PID=60) to work on /opt/airflow/dags/sf311_data_upload_dag.py
[2024-02-02T17:11:31.052+0000] {processor.py:830} INFO - Processing file /opt/airflow/dags/sf311_data_upload_dag.py for tasks to queue
[2024-02-02T17:11:31.055+0000] {logging_mixin.py:188} INFO - [2024-02-02T17:11:31.055+0000] {dagbag.py:538} INFO - Filling up the DagBag from /opt/airflow/dags/sf311_data_upload_dag.py
[2024-02-02T17:11:31.064+0000] {logging_mixin.py:188} INFO - [2024-02-02T17:11:31.062+0000] {dagbag.py:348} ERROR - Failed to import: /opt/airflow/dags/sf311_data_upload_dag.py
Traceback (most recent call last):
  File "/home/airflow/.local/lib/python3.8/site-packages/airflow/models/dagbag.py", line 344, in parse
    loader.exec_module(new_module)
  File "<frozen importlib._bootstrap_external>", line 843, in exec_module
  File "<frozen importlib._bootstrap>", line 219, in _call_with_frames_removed
  File "/opt/airflow/dags/sf311_data_upload_dag.py", line 5, in <module>
    from airflow import PythonOperator
ImportError: cannot import name 'PythonOperator' from 'airflow' (/home/airflow/.local/lib/python3.8/site-packages/airflow/__init__.py)
[2024-02-02T17:11:31.065+0000] {processor.py:842} WARNING - No viable dags retrieved from /opt/airflow/dags/sf311_data_upload_dag.py
[2024-02-02T17:11:31.080+0000] {processor.py:183} INFO - Processing /opt/airflow/dags/sf311_data_upload_dag.py took 0.035 seconds
[2024-02-02T17:12:01.333+0000] {processor.py:161} INFO - Started process (PID=67) to work on /opt/airflow/dags/sf311_data_upload_dag.py
[2024-02-02T17:12:01.336+0000] {processor.py:830} INFO - Processing file /opt/airflow/dags/sf311_data_upload_dag.py for tasks to queue
[2024-02-02T17:12:01.341+0000] {logging_mixin.py:188} INFO - [2024-02-02T17:12:01.340+0000] {dagbag.py:538} INFO - Filling up the DagBag from /opt/airflow/dags/sf311_data_upload_dag.py
[2024-02-02T17:12:01.354+0000] {logging_mixin.py:188} INFO - [2024-02-02T17:12:01.351+0000] {dagbag.py:348} ERROR - Failed to import: /opt/airflow/dags/sf311_data_upload_dag.py
Traceback (most recent call last):
  File "/home/airflow/.local/lib/python3.8/site-packages/airflow/models/dagbag.py", line 344, in parse
    loader.exec_module(new_module)
  File "<frozen importlib._bootstrap_external>", line 843, in exec_module
  File "<frozen importlib._bootstrap>", line 219, in _call_with_frames_removed
  File "/opt/airflow/dags/sf311_data_upload_dag.py", line 5, in <module>
    from airflow import PythonOperator
ImportError: cannot import name 'PythonOperator' from 'airflow' (/home/airflow/.local/lib/python3.8/site-packages/airflow/__init__.py)
[2024-02-02T17:12:01.358+0000] {processor.py:842} WARNING - No viable dags retrieved from /opt/airflow/dags/sf311_data_upload_dag.py
[2024-02-02T17:12:01.382+0000] {processor.py:183} INFO - Processing /opt/airflow/dags/sf311_data_upload_dag.py took 0.055 seconds
[2024-02-02T17:12:31.580+0000] {processor.py:161} INFO - Started process (PID=74) to work on /opt/airflow/dags/sf311_data_upload_dag.py
[2024-02-02T17:12:31.582+0000] {processor.py:830} INFO - Processing file /opt/airflow/dags/sf311_data_upload_dag.py for tasks to queue
[2024-02-02T17:12:31.585+0000] {logging_mixin.py:188} INFO - [2024-02-02T17:12:31.585+0000] {dagbag.py:538} INFO - Filling up the DagBag from /opt/airflow/dags/sf311_data_upload_dag.py
[2024-02-02T17:12:31.597+0000] {logging_mixin.py:188} INFO - [2024-02-02T17:12:31.594+0000] {dagbag.py:348} ERROR - Failed to import: /opt/airflow/dags/sf311_data_upload_dag.py
Traceback (most recent call last):
  File "/home/airflow/.local/lib/python3.8/site-packages/airflow/models/dagbag.py", line 344, in parse
    loader.exec_module(new_module)
  File "<frozen importlib._bootstrap_external>", line 843, in exec_module
  File "<frozen importlib._bootstrap>", line 219, in _call_with_frames_removed
  File "/opt/airflow/dags/sf311_data_upload_dag.py", line 5, in <module>
    from airflow import PythonOperator
ImportError: cannot import name 'PythonOperator' from 'airflow' (/home/airflow/.local/lib/python3.8/site-packages/airflow/__init__.py)
[2024-02-02T17:12:31.598+0000] {processor.py:842} WARNING - No viable dags retrieved from /opt/airflow/dags/sf311_data_upload_dag.py
[2024-02-02T17:12:31.612+0000] {processor.py:183} INFO - Processing /opt/airflow/dags/sf311_data_upload_dag.py took 0.037 seconds
[2024-02-02T17:13:01.852+0000] {processor.py:161} INFO - Started process (PID=81) to work on /opt/airflow/dags/sf311_data_upload_dag.py
[2024-02-02T17:13:01.855+0000] {processor.py:830} INFO - Processing file /opt/airflow/dags/sf311_data_upload_dag.py for tasks to queue
[2024-02-02T17:13:01.858+0000] {logging_mixin.py:188} INFO - [2024-02-02T17:13:01.857+0000] {dagbag.py:538} INFO - Filling up the DagBag from /opt/airflow/dags/sf311_data_upload_dag.py
[2024-02-02T17:13:01.869+0000] {logging_mixin.py:188} INFO - [2024-02-02T17:13:01.866+0000] {dagbag.py:348} ERROR - Failed to import: /opt/airflow/dags/sf311_data_upload_dag.py
Traceback (most recent call last):
  File "/home/airflow/.local/lib/python3.8/site-packages/airflow/models/dagbag.py", line 344, in parse
    loader.exec_module(new_module)
  File "<frozen importlib._bootstrap_external>", line 843, in exec_module
  File "<frozen importlib._bootstrap>", line 219, in _call_with_frames_removed
  File "/opt/airflow/dags/sf311_data_upload_dag.py", line 5, in <module>
    from airflow import PythonOperator
ImportError: cannot import name 'PythonOperator' from 'airflow' (/home/airflow/.local/lib/python3.8/site-packages/airflow/__init__.py)
[2024-02-02T17:13:01.870+0000] {processor.py:842} WARNING - No viable dags retrieved from /opt/airflow/dags/sf311_data_upload_dag.py
[2024-02-02T17:13:01.885+0000] {processor.py:183} INFO - Processing /opt/airflow/dags/sf311_data_upload_dag.py took 0.037 seconds
[2024-02-02T17:13:32.165+0000] {processor.py:161} INFO - Started process (PID=88) to work on /opt/airflow/dags/sf311_data_upload_dag.py
[2024-02-02T17:13:32.167+0000] {processor.py:830} INFO - Processing file /opt/airflow/dags/sf311_data_upload_dag.py for tasks to queue
[2024-02-02T17:13:32.174+0000] {logging_mixin.py:188} INFO - [2024-02-02T17:13:32.173+0000] {dagbag.py:538} INFO - Filling up the DagBag from /opt/airflow/dags/sf311_data_upload_dag.py
[2024-02-02T17:13:32.195+0000] {logging_mixin.py:188} INFO - [2024-02-02T17:13:32.191+0000] {dagbag.py:348} ERROR - Failed to import: /opt/airflow/dags/sf311_data_upload_dag.py
Traceback (most recent call last):
  File "/home/airflow/.local/lib/python3.8/site-packages/airflow/models/dagbag.py", line 344, in parse
    loader.exec_module(new_module)
  File "<frozen importlib._bootstrap_external>", line 843, in exec_module
  File "<frozen importlib._bootstrap>", line 219, in _call_with_frames_removed
  File "/opt/airflow/dags/sf311_data_upload_dag.py", line 5, in <module>
    from airflow import PythonOperator
ImportError: cannot import name 'PythonOperator' from 'airflow' (/home/airflow/.local/lib/python3.8/site-packages/airflow/__init__.py)
[2024-02-02T17:13:32.196+0000] {processor.py:842} WARNING - No viable dags retrieved from /opt/airflow/dags/sf311_data_upload_dag.py
[2024-02-02T17:13:32.223+0000] {processor.py:183} INFO - Processing /opt/airflow/dags/sf311_data_upload_dag.py took 0.062 seconds
[2024-02-02T17:24:59.026+0000] {processor.py:161} INFO - Started process (PID=32) to work on /opt/airflow/dags/sf311_data_upload_dag.py
[2024-02-02T17:24:59.032+0000] {processor.py:830} INFO - Processing file /opt/airflow/dags/sf311_data_upload_dag.py for tasks to queue
[2024-02-02T17:24:59.036+0000] {logging_mixin.py:188} INFO - [2024-02-02T17:24:59.036+0000] {dagbag.py:538} INFO - Filling up the DagBag from /opt/airflow/dags/sf311_data_upload_dag.py
[2024-02-02T17:24:59.163+0000] {logging_mixin.py:188} INFO - [2024-02-02T17:24:59.155+0000] {dagbag.py:348} ERROR - Failed to import: /opt/airflow/dags/sf311_data_upload_dag.py
Traceback (most recent call last):
  File "/home/airflow/.local/lib/python3.8/site-packages/airflow/models/dagbag.py", line 344, in parse
    loader.exec_module(new_module)
  File "<frozen importlib._bootstrap_external>", line 843, in exec_module
  File "<frozen importlib._bootstrap>", line 219, in _call_with_frames_removed
  File "/opt/airflow/dags/sf311_data_upload_dag.py", line 10, in <module>
    import sf311_s3_upload
  File "/opt/airflow/dags/sf311_s3_upload.py", line 1, in <module>
    from plugins.s3_csv import open_s3
ModuleNotFoundError: No module named 'plugins'
[2024-02-02T17:24:59.165+0000] {processor.py:842} WARNING - No viable dags retrieved from /opt/airflow/dags/sf311_data_upload_dag.py
[2024-02-02T17:24:59.196+0000] {processor.py:183} INFO - Processing /opt/airflow/dags/sf311_data_upload_dag.py took 0.172 seconds
[2024-02-02T17:25:29.377+0000] {processor.py:161} INFO - Started process (PID=40) to work on /opt/airflow/dags/sf311_data_upload_dag.py
[2024-02-02T17:25:29.380+0000] {processor.py:830} INFO - Processing file /opt/airflow/dags/sf311_data_upload_dag.py for tasks to queue
[2024-02-02T17:25:29.384+0000] {logging_mixin.py:188} INFO - [2024-02-02T17:25:29.383+0000] {dagbag.py:538} INFO - Filling up the DagBag from /opt/airflow/dags/sf311_data_upload_dag.py
[2024-02-02T17:25:29.413+0000] {logging_mixin.py:188} INFO - [2024-02-02T17:25:29.410+0000] {dagbag.py:348} ERROR - Failed to import: /opt/airflow/dags/sf311_data_upload_dag.py
Traceback (most recent call last):
  File "/home/airflow/.local/lib/python3.8/site-packages/airflow/models/dagbag.py", line 344, in parse
    loader.exec_module(new_module)
  File "<frozen importlib._bootstrap_external>", line 843, in exec_module
  File "<frozen importlib._bootstrap>", line 219, in _call_with_frames_removed
  File "/opt/airflow/dags/sf311_data_upload_dag.py", line 10, in <module>
    import sf311_s3_upload
  File "/opt/airflow/dags/sf311_s3_upload.py", line 1, in <module>
    from plugins.s3_csv import open_s3
ModuleNotFoundError: No module named 'plugins'
[2024-02-02T17:25:29.414+0000] {processor.py:842} WARNING - No viable dags retrieved from /opt/airflow/dags/sf311_data_upload_dag.py
[2024-02-02T17:25:29.433+0000] {processor.py:183} INFO - Processing /opt/airflow/dags/sf311_data_upload_dag.py took 0.062 seconds
[2024-02-02T17:25:59.694+0000] {processor.py:161} INFO - Started process (PID=47) to work on /opt/airflow/dags/sf311_data_upload_dag.py
[2024-02-02T17:25:59.697+0000] {processor.py:830} INFO - Processing file /opt/airflow/dags/sf311_data_upload_dag.py for tasks to queue
[2024-02-02T17:25:59.701+0000] {logging_mixin.py:188} INFO - [2024-02-02T17:25:59.700+0000] {dagbag.py:538} INFO - Filling up the DagBag from /opt/airflow/dags/sf311_data_upload_dag.py
[2024-02-02T17:25:59.729+0000] {logging_mixin.py:188} INFO - [2024-02-02T17:25:59.726+0000] {dagbag.py:348} ERROR - Failed to import: /opt/airflow/dags/sf311_data_upload_dag.py
Traceback (most recent call last):
  File "/home/airflow/.local/lib/python3.8/site-packages/airflow/models/dagbag.py", line 344, in parse
    loader.exec_module(new_module)
  File "<frozen importlib._bootstrap_external>", line 843, in exec_module
  File "<frozen importlib._bootstrap>", line 219, in _call_with_frames_removed
  File "/opt/airflow/dags/sf311_data_upload_dag.py", line 10, in <module>
    import sf311_s3_upload
  File "/opt/airflow/dags/sf311_s3_upload.py", line 1, in <module>
    from plugins.s3_csv import open_s3
ModuleNotFoundError: No module named 'plugins'
[2024-02-02T17:25:59.730+0000] {processor.py:842} WARNING - No viable dags retrieved from /opt/airflow/dags/sf311_data_upload_dag.py
[2024-02-02T17:25:59.766+0000] {processor.py:183} INFO - Processing /opt/airflow/dags/sf311_data_upload_dag.py took 0.077 seconds
[2024-02-02T17:26:30.085+0000] {processor.py:161} INFO - Started process (PID=54) to work on /opt/airflow/dags/sf311_data_upload_dag.py
[2024-02-02T17:26:30.087+0000] {processor.py:830} INFO - Processing file /opt/airflow/dags/sf311_data_upload_dag.py for tasks to queue
[2024-02-02T17:26:30.090+0000] {logging_mixin.py:188} INFO - [2024-02-02T17:26:30.090+0000] {dagbag.py:538} INFO - Filling up the DagBag from /opt/airflow/dags/sf311_data_upload_dag.py
[2024-02-02T17:26:30.108+0000] {logging_mixin.py:188} INFO - [2024-02-02T17:26:30.104+0000] {dagbag.py:348} ERROR - Failed to import: /opt/airflow/dags/sf311_data_upload_dag.py
Traceback (most recent call last):
  File "/home/airflow/.local/lib/python3.8/site-packages/airflow/models/dagbag.py", line 344, in parse
    loader.exec_module(new_module)
  File "<frozen importlib._bootstrap_external>", line 843, in exec_module
  File "<frozen importlib._bootstrap>", line 219, in _call_with_frames_removed
  File "/opt/airflow/dags/sf311_data_upload_dag.py", line 10, in <module>
    import sf311_s3_upload
  File "/opt/airflow/dags/sf311_s3_upload.py", line 1, in <module>
    from plugins.s3_csv import open_s3
ModuleNotFoundError: No module named 'plugins'
[2024-02-02T17:26:30.109+0000] {processor.py:842} WARNING - No viable dags retrieved from /opt/airflow/dags/sf311_data_upload_dag.py
[2024-02-02T17:26:30.125+0000] {processor.py:183} INFO - Processing /opt/airflow/dags/sf311_data_upload_dag.py took 0.044 seconds
[2024-02-02T17:27:00.391+0000] {processor.py:161} INFO - Started process (PID=61) to work on /opt/airflow/dags/sf311_data_upload_dag.py
[2024-02-02T17:27:00.393+0000] {processor.py:830} INFO - Processing file /opt/airflow/dags/sf311_data_upload_dag.py for tasks to queue
[2024-02-02T17:27:00.396+0000] {logging_mixin.py:188} INFO - [2024-02-02T17:27:00.396+0000] {dagbag.py:538} INFO - Filling up the DagBag from /opt/airflow/dags/sf311_data_upload_dag.py
[2024-02-02T17:27:00.416+0000] {logging_mixin.py:188} INFO - [2024-02-02T17:27:00.411+0000] {dagbag.py:348} ERROR - Failed to import: /opt/airflow/dags/sf311_data_upload_dag.py
Traceback (most recent call last):
  File "/home/airflow/.local/lib/python3.8/site-packages/airflow/models/dagbag.py", line 344, in parse
    loader.exec_module(new_module)
  File "<frozen importlib._bootstrap_external>", line 843, in exec_module
  File "<frozen importlib._bootstrap>", line 219, in _call_with_frames_removed
  File "/opt/airflow/dags/sf311_data_upload_dag.py", line 10, in <module>
    import sf311_s3_upload
  File "/opt/airflow/dags/sf311_s3_upload.py", line 1, in <module>
    from plugins.s3_csv import open_s3
ModuleNotFoundError: No module named 'plugins'
[2024-02-02T17:27:00.420+0000] {processor.py:842} WARNING - No viable dags retrieved from /opt/airflow/dags/sf311_data_upload_dag.py
[2024-02-02T17:27:00.441+0000] {processor.py:183} INFO - Processing /opt/airflow/dags/sf311_data_upload_dag.py took 0.053 seconds
[2024-02-02T17:27:30.738+0000] {processor.py:161} INFO - Started process (PID=68) to work on /opt/airflow/dags/sf311_data_upload_dag.py
[2024-02-02T17:27:30.740+0000] {processor.py:830} INFO - Processing file /opt/airflow/dags/sf311_data_upload_dag.py for tasks to queue
[2024-02-02T17:27:30.745+0000] {logging_mixin.py:188} INFO - [2024-02-02T17:27:30.744+0000] {dagbag.py:538} INFO - Filling up the DagBag from /opt/airflow/dags/sf311_data_upload_dag.py
[2024-02-02T17:27:30.764+0000] {logging_mixin.py:188} INFO - [2024-02-02T17:27:30.761+0000] {dagbag.py:348} ERROR - Failed to import: /opt/airflow/dags/sf311_data_upload_dag.py
Traceback (most recent call last):
  File "/home/airflow/.local/lib/python3.8/site-packages/airflow/models/dagbag.py", line 344, in parse
    loader.exec_module(new_module)
  File "<frozen importlib._bootstrap_external>", line 843, in exec_module
  File "<frozen importlib._bootstrap>", line 219, in _call_with_frames_removed
  File "/opt/airflow/dags/sf311_data_upload_dag.py", line 10, in <module>
    import sf311_s3_upload
  File "/opt/airflow/dags/sf311_s3_upload.py", line 1, in <module>
    from plugins.s3_csv import open_s3
ModuleNotFoundError: No module named 'plugins'
[2024-02-02T17:27:30.765+0000] {processor.py:842} WARNING - No viable dags retrieved from /opt/airflow/dags/sf311_data_upload_dag.py
[2024-02-02T17:27:30.781+0000] {processor.py:183} INFO - Processing /opt/airflow/dags/sf311_data_upload_dag.py took 0.048 seconds
