[2024-02-04T09:49:50.152+0000] {taskinstance.py:1956} INFO - Dependencies all met for dep_context=non-requeueable deps ti=<TaskInstance: sf_data_upload.sf311_s3_upload_task scheduled__2024-02-02T00:00:00+00:00 [queued]>
[2024-02-04T09:49:50.170+0000] {taskinstance.py:1956} INFO - Dependencies all met for dep_context=requeueable deps ti=<TaskInstance: sf_data_upload.sf311_s3_upload_task scheduled__2024-02-02T00:00:00+00:00 [queued]>
[2024-02-04T09:49:50.172+0000] {taskinstance.py:2170} INFO - Starting attempt 9 of 9
[2024-02-04T09:49:50.181+0000] {taskinstance.py:2191} INFO - Executing <Task(PythonOperator): sf311_s3_upload_task> on 2024-02-02 00:00:00+00:00
[2024-02-04T09:49:50.187+0000] {standard_task_runner.py:60} INFO - Started process 55 to run task
[2024-02-04T09:49:50.194+0000] {standard_task_runner.py:87} INFO - Running: ['***', 'tasks', 'run', 'sf_data_upload', 'sf311_s3_upload_task', 'scheduled__2024-02-02T00:00:00+00:00', '--job-id', '52', '--raw', '--subdir', 'DAGS_FOLDER/sf311_data_upload_dag.py', '--cfg-path', '/tmp/tmp009tdjb0']
[2024-02-04T09:49:50.197+0000] {standard_task_runner.py:88} INFO - Job 52: Subtask sf311_s3_upload_task
[2024-02-04T09:49:50.257+0000] {task_command.py:423} INFO - Running <TaskInstance: sf_data_upload.sf311_s3_upload_task scheduled__2024-02-02T00:00:00+00:00 [running]> on host d077c89f140d
[2024-02-04T09:49:50.777+0000] {taskinstance.py:2480} INFO - Exporting env vars: AIRFLOW_CTX_DAG_OWNER='***' AIRFLOW_CTX_DAG_ID='sf_data_upload' AIRFLOW_CTX_TASK_ID='sf311_s3_upload_task' AIRFLOW_CTX_EXECUTION_DATE='2024-02-02T00:00:00+00:00' AIRFLOW_CTX_TRY_NUMBER='9' AIRFLOW_CTX_DAG_RUN_ID='scheduled__2024-02-02T00:00:00+00:00'
[2024-02-04T09:49:50.797+0000] {base.py:83} INFO - Using connection ID 'aws_default' for task execution.
[2024-02-04T09:49:50.799+0000] {connection_wrapper.py:378} INFO - AWS Connection (conn_id='aws_default', conn_type='aws') credentials retrieved from login and password.
[2024-02-04T09:49:51.880+0000] {taskinstance.py:2698} ERROR - Task failed with exception
Traceback (most recent call last):
  File "/home/airflow/.local/lib/python3.8/site-packages/airflow/models/taskinstance.py", line 433, in _execute_task
    result = execute_callable(context=context, **execute_callable_kwargs)
  File "/home/airflow/.local/lib/python3.8/site-packages/airflow/operators/python.py", line 199, in execute
    return_value = self.execute_callable()
  File "/home/airflow/.local/lib/python3.8/site-packages/airflow/operators/python.py", line 216, in execute_callable
    return self.python_callable(*self.op_args, **self.op_kwargs)
  File "/opt/airflow/dags/sf311_data_upload_dag.py", line 46, in upload_to_s3_hook
    s3_hook.load_file(filename=df, key=int_311_key, bucket_name=s3_bucket_name)
  File "/home/airflow/.local/lib/python3.8/site-packages/airflow/providers/amazon/aws/hooks/s3.py", line 137, in wrapper
    return func(*bound_args.args, **bound_args.kwargs)
  File "/home/airflow/.local/lib/python3.8/site-packages/airflow/providers/amazon/aws/hooks/s3.py", line 91, in wrapper
    return func(*bound_args.args, **bound_args.kwargs)
  File "/home/airflow/.local/lib/python3.8/site-packages/airflow/providers/amazon/aws/hooks/s3.py", line 1090, in load_file
    client.upload_file(filename, bucket_name, key, ExtraArgs=extra_args, Config=self.transfer_config)
  File "/home/airflow/.local/lib/python3.8/site-packages/boto3/s3/inject.py", line 143, in upload_file
    return transfer.upload_file(
  File "/home/airflow/.local/lib/python3.8/site-packages/boto3/s3/transfer.py", line 288, in upload_file
    future.result()
  File "/home/airflow/.local/lib/python3.8/site-packages/s3transfer/futures.py", line 103, in result
    return self._coordinator.result()
  File "/home/airflow/.local/lib/python3.8/site-packages/s3transfer/futures.py", line 266, in result
    raise self._exception
  File "/home/airflow/.local/lib/python3.8/site-packages/s3transfer/tasks.py", line 269, in _main
    self._submit(transfer_future=transfer_future, **kwargs)
  File "/home/airflow/.local/lib/python3.8/site-packages/s3transfer/upload.py", line 585, in _submit
    upload_input_manager.provide_transfer_size(transfer_future)
  File "/home/airflow/.local/lib/python3.8/site-packages/s3transfer/upload.py", line 244, in provide_transfer_size
    self._osutil.get_file_size(transfer_future.meta.call_args.fileobj)
  File "/home/airflow/.local/lib/python3.8/site-packages/s3transfer/utils.py", line 247, in get_file_size
    return os.path.getsize(filename)
  File "/usr/local/lib/python3.8/genericpath.py", line 50, in getsize
    return os.stat(filename).st_size
OSError: [Errno 36] File name too long: '     service_request_id  requested_datetime  ...        lat        long\n0              17841168 2024-02-02 01:29:22  ...  37.760777 -122.434918\n1              17841162 2024-02-02 01:18:09  ...  37.786462 -122.395753\n2              17841161 2024-02-02 01:18:02  ...  37.776938 -122.472381\n3              17841158 2024-02-02 01:13:00  ...  37.788118 -122.418045\n4              17841157 2024-02-02 01:12:00  ...  37.786300 -122.414555\n..                  ...                 ...  ...        ...         ...\n995            17838519 2024-02-01 11:08:00  ...  37.778366 -122.402695\n996            17838518 2024-02-01 11:08:00  ...  37.746839 -122.414077\n997            17838516 2024-02-01 11:07:38  ...  37.763809 -122.471529\n998            17838515 2024-02-01 11:07:00  ...  37.733290 -122.444328\n999            17838507 2024-02-01 11:05:00  ...   0.000000    0.000000\n\n[1000 rows x 21 columns]'
[2024-02-04T09:49:51.894+0000] {taskinstance.py:1138} INFO - Marking task as FAILED. dag_id=sf_data_upload, task_id=sf311_s3_upload_task, execution_date=20240202T000000, start_date=20240204T094950, end_date=20240204T094951
[2024-02-04T09:49:51.918+0000] {standard_task_runner.py:107} ERROR - Failed to execute job 52 for task sf311_s3_upload_task ([Errno 36] File name too long: '     service_request_id  requested_datetime  ...        lat        long\n0              17841168 2024-02-02 01:29:22  ...  37.760777 -122.434918\n1              17841162 2024-02-02 01:18:09  ...  37.786462 -122.395753\n2              17841161 2024-02-02 01:18:02  ...  37.776938 -122.472381\n3              17841158 2024-02-02 01:13:00  ...  37.788118 -122.418045\n4              17841157 2024-02-02 01:12:00  ...  37.786300 -122.414555\n..                  ...                 ...  ...        ...         ...\n995            17838519 2024-02-01 11:08:00  ...  37.778366 -122.402695\n996            17838518 2024-02-01 11:08:00  ...  37.746839 -122.414077\n997            17838516 2024-02-01 11:07:38  ...  37.763809 -122.471529\n998            17838515 2024-02-01 11:07:00  ...  37.733290 -122.444328\n999            17838507 2024-02-01 11:05:00  ...   0.000000    0.000000\n\n[1000 rows x 21 columns]'; 55)
[2024-02-04T09:49:51.981+0000] {local_task_job_runner.py:234} INFO - Task exited with return code 1
[2024-02-04T09:49:52.032+0000] {taskinstance.py:3280} INFO - 0 downstream tasks scheduled from follow-on schedule check
