[2024-02-04T09:37:24.049+0000] {taskinstance.py:1956} INFO - Dependencies all met for dep_context=non-requeueable deps ti=<TaskInstance: sf_data_upload.sf311_s3_upload_task scheduled__2024-02-02T00:00:00+00:00 [queued]>
[2024-02-04T09:37:24.056+0000] {taskinstance.py:1956} INFO - Dependencies all met for dep_context=requeueable deps ti=<TaskInstance: sf_data_upload.sf311_s3_upload_task scheduled__2024-02-02T00:00:00+00:00 [queued]>
[2024-02-04T09:37:24.057+0000] {taskinstance.py:2170} INFO - Starting attempt 8 of 8
[2024-02-04T09:37:24.065+0000] {taskinstance.py:2191} INFO - Executing <Task(PythonOperator): sf311_s3_upload_task> on 2024-02-02 00:00:00+00:00
[2024-02-04T09:37:24.070+0000] {standard_task_runner.py:60} INFO - Started process 57 to run task
[2024-02-04T09:37:24.073+0000] {standard_task_runner.py:87} INFO - Running: ['***', 'tasks', 'run', 'sf_data_upload', 'sf311_s3_upload_task', 'scheduled__2024-02-02T00:00:00+00:00', '--job-id', '49', '--raw', '--subdir', 'DAGS_FOLDER/sf311_data_upload_dag.py', '--cfg-path', '/tmp/tmpantilkdm']
[2024-02-04T09:37:24.074+0000] {standard_task_runner.py:88} INFO - Job 49: Subtask sf311_s3_upload_task
[2024-02-04T09:37:24.107+0000] {task_command.py:423} INFO - Running <TaskInstance: sf_data_upload.sf311_s3_upload_task scheduled__2024-02-02T00:00:00+00:00 [running]> on host acc0f6caf03f
[2024-02-04T09:37:24.499+0000] {taskinstance.py:2480} INFO - Exporting env vars: AIRFLOW_CTX_DAG_OWNER='***' AIRFLOW_CTX_DAG_ID='sf_data_upload' AIRFLOW_CTX_TASK_ID='sf311_s3_upload_task' AIRFLOW_CTX_EXECUTION_DATE='2024-02-02T00:00:00+00:00' AIRFLOW_CTX_TRY_NUMBER='8' AIRFLOW_CTX_DAG_RUN_ID='scheduled__2024-02-02T00:00:00+00:00'
[2024-02-04T09:37:25.639+0000] {taskinstance.py:2698} ERROR - Task failed with exception
Traceback (most recent call last):
  File "/home/airflow/.local/lib/python3.8/site-packages/airflow/models/taskinstance.py", line 433, in _execute_task
    result = execute_callable(context=context, **execute_callable_kwargs)
  File "/home/airflow/.local/lib/python3.8/site-packages/airflow/operators/python.py", line 199, in execute
    return_value = self.execute_callable()
  File "/home/airflow/.local/lib/python3.8/site-packages/airflow/operators/python.py", line 216, in execute_callable
    return self.python_callable(*self.op_args, **self.op_kwargs)
  File "/opt/airflow/plugins/sf311_s3_upload.py", line 38, in upload_to_s3_new
    s3_client.put_object(Bucket=bucket, Key = int_311_key, Body = csv_buffer.getvalue())
  File "/home/airflow/.local/lib/python3.8/site-packages/botocore/client.py", line 415, in _api_call
    return self._make_api_call(operation_name, kwargs)
  File "/home/airflow/.local/lib/python3.8/site-packages/botocore/client.py", line 731, in _make_api_call
    http, parsed_response = self._make_request(
  File "/home/airflow/.local/lib/python3.8/site-packages/botocore/client.py", line 751, in _make_request
    return self._endpoint.make_request(operation_model, request_dict)
  File "/home/airflow/.local/lib/python3.8/site-packages/botocore/endpoint.py", line 107, in make_request
    return self._send_request(request_dict, operation_model)
  File "/home/airflow/.local/lib/python3.8/site-packages/botocore/endpoint.py", line 180, in _send_request
    request = self.create_request(request_dict, operation_model)
  File "/home/airflow/.local/lib/python3.8/site-packages/botocore/endpoint.py", line 120, in create_request
    self._event_emitter.emit(event_name, request=request,
  File "/home/airflow/.local/lib/python3.8/site-packages/botocore/hooks.py", line 358, in emit
    return self._emitter.emit(aliased_event_name, **kwargs)
  File "/home/airflow/.local/lib/python3.8/site-packages/botocore/hooks.py", line 229, in emit
    return self._emit(event_name, kwargs)
  File "/home/airflow/.local/lib/python3.8/site-packages/botocore/hooks.py", line 212, in _emit
    response = handler(**kwargs)
  File "/home/airflow/.local/lib/python3.8/site-packages/botocore/signers.py", line 95, in handler
    return self.sign(operation_name, request)
  File "/home/airflow/.local/lib/python3.8/site-packages/botocore/signers.py", line 167, in sign
    auth.add_auth(request)
  File "/home/airflow/.local/lib/python3.8/site-packages/botocore/auth.py", line 401, in add_auth
    raise NoCredentialsError()
botocore.exceptions.NoCredentialsError: Unable to locate credentials
[2024-02-04T09:37:25.649+0000] {taskinstance.py:1138} INFO - Marking task as FAILED. dag_id=sf_data_upload, task_id=sf311_s3_upload_task, execution_date=20240202T000000, start_date=20240204T093724, end_date=20240204T093725
[2024-02-04T09:37:25.657+0000] {standard_task_runner.py:107} ERROR - Failed to execute job 49 for task sf311_s3_upload_task (Unable to locate credentials; 57)
[2024-02-04T09:37:25.709+0000] {local_task_job_runner.py:234} INFO - Task exited with return code 1
[2024-02-04T09:37:25.723+0000] {taskinstance.py:3280} INFO - 0 downstream tasks scheduled from follow-on schedule check
