[2024-02-04T09:58:23.222+0000] {taskinstance.py:1956} INFO - Dependencies all met for dep_context=non-requeueable deps ti=<TaskInstance: sf_data_upload.sf311_extract_task manual__2024-02-04T09:55:54.011497+00:00 [queued]>
[2024-02-04T09:58:23.231+0000] {taskinstance.py:1956} INFO - Dependencies all met for dep_context=requeueable deps ti=<TaskInstance: sf_data_upload.sf311_extract_task manual__2024-02-04T09:55:54.011497+00:00 [queued]>
[2024-02-04T09:58:23.233+0000] {taskinstance.py:2170} INFO - Starting attempt 4 of 4
[2024-02-04T09:58:23.242+0000] {taskinstance.py:2191} INFO - Executing <Task(PythonOperator): sf311_extract_task> on 2024-02-04 09:55:54.011497+00:00
[2024-02-04T09:58:23.248+0000] {standard_task_runner.py:60} INFO - Started process 49 to run task
[2024-02-04T09:58:23.251+0000] {standard_task_runner.py:87} INFO - Running: ['***', 'tasks', 'run', 'sf_data_upload', 'sf311_extract_task', 'manual__2024-02-04T09:55:54.011497+00:00', '--job-id', '61', '--raw', '--subdir', 'DAGS_FOLDER/sf311_data_upload_dag.py', '--cfg-path', '/tmp/tmpn7ic9i_g']
[2024-02-04T09:58:23.255+0000] {standard_task_runner.py:88} INFO - Job 61: Subtask sf311_extract_task
[2024-02-04T09:58:23.325+0000] {task_command.py:423} INFO - Running <TaskInstance: sf_data_upload.sf311_extract_task manual__2024-02-04T09:55:54.011497+00:00 [running]> on host e61977183ded
[2024-02-04T09:58:23.417+0000] {taskinstance.py:2480} INFO - Exporting env vars: AIRFLOW_CTX_DAG_OWNER='***' AIRFLOW_CTX_DAG_ID='sf_data_upload' AIRFLOW_CTX_TASK_ID='sf311_extract_task' AIRFLOW_CTX_EXECUTION_DATE='2024-02-04T09:55:54.011497+00:00' AIRFLOW_CTX_TRY_NUMBER='4' AIRFLOW_CTX_DAG_RUN_ID='manual__2024-02-04T09:55:54.011497+00:00'
[2024-02-04T09:58:23.860+0000] {socrata.py:63} WARNING - Requests made without an app_token will be subject to strict throttling limits.
[2024-02-04T09:58:34.272+0000] {taskinstance.py:2698} ERROR - Task failed with exception
Traceback (most recent call last):
  File "/home/airflow/.local/lib/python3.8/site-packages/urllib3/connectionpool.py", line 467, in _make_request
    six.raise_from(e, None)
  File "<string>", line 3, in raise_from
  File "/home/airflow/.local/lib/python3.8/site-packages/urllib3/connectionpool.py", line 462, in _make_request
    httplib_response = conn.getresponse()
  File "/usr/local/lib/python3.8/http/client.py", line 1348, in getresponse
    response.begin()
  File "/usr/local/lib/python3.8/http/client.py", line 316, in begin
    version, status, reason = self._read_status()
  File "/usr/local/lib/python3.8/http/client.py", line 277, in _read_status
    line = str(self.fp.readline(_MAXLINE + 1), "iso-8859-1")
  File "/usr/local/lib/python3.8/socket.py", line 669, in readinto
    return self._sock.recv_into(b)
  File "/usr/local/lib/python3.8/ssl.py", line 1274, in recv_into
    return self.read(nbytes, buffer)
  File "/usr/local/lib/python3.8/ssl.py", line 1132, in read
    return self._sslobj.read(len, buffer)
socket.timeout: The read operation timed out

During handling of the above exception, another exception occurred:

Traceback (most recent call last):
  File "/home/airflow/.local/lib/python3.8/site-packages/requests/adapters.py", line 486, in send
    resp = conn.urlopen(
  File "/home/airflow/.local/lib/python3.8/site-packages/urllib3/connectionpool.py", line 799, in urlopen
    retries = retries.increment(
  File "/home/airflow/.local/lib/python3.8/site-packages/urllib3/util/retry.py", line 550, in increment
    raise six.reraise(type(error), error, _stacktrace)
  File "/home/airflow/.local/lib/python3.8/site-packages/urllib3/packages/six.py", line 770, in reraise
    raise value
  File "/home/airflow/.local/lib/python3.8/site-packages/urllib3/connectionpool.py", line 715, in urlopen
    httplib_response = self._make_request(
  File "/home/airflow/.local/lib/python3.8/site-packages/urllib3/connectionpool.py", line 469, in _make_request
    self._raise_timeout(err=e, url=url, timeout_value=read_timeout)
  File "/home/airflow/.local/lib/python3.8/site-packages/urllib3/connectionpool.py", line 358, in _raise_timeout
    raise ReadTimeoutError(
urllib3.exceptions.ReadTimeoutError: HTTPSConnectionPool(host='data.sfgov.org', port=443): Read timed out. (read timeout=10)

During handling of the above exception, another exception occurred:

Traceback (most recent call last):
  File "/home/airflow/.local/lib/python3.8/site-packages/airflow/models/taskinstance.py", line 433, in _execute_task
    result = execute_callable(context=context, **execute_callable_kwargs)
  File "/home/airflow/.local/lib/python3.8/site-packages/airflow/operators/python.py", line 199, in execute
    return_value = self.execute_callable()
  File "/home/airflow/.local/lib/python3.8/site-packages/airflow/operators/python.py", line 216, in execute_callable
    return self.python_callable(*self.op_args, **self.op_kwargs)
  File "/opt/airflow/plugins/sf311_extract.py", line 34, in pull_opensf_data
    results = client.get(endpoint, limit = limit, offset = offset, where=filters)
  File "/home/airflow/.local/lib/python3.8/site-packages/sodapy/socrata.py", line 412, in get
    response = self._perform_request(
  File "/home/airflow/.local/lib/python3.8/site-packages/sodapy/socrata.py", line 551, in _perform_request
    response = getattr(self.session, request_type)(uri, **kwargs)
  File "/home/airflow/.local/lib/python3.8/site-packages/requests/sessions.py", line 602, in get
    return self.request("GET", url, **kwargs)
  File "/home/airflow/.local/lib/python3.8/site-packages/requests/sessions.py", line 589, in request
    resp = self.send(prep, **send_kwargs)
  File "/home/airflow/.local/lib/python3.8/site-packages/requests/sessions.py", line 703, in send
    r = adapter.send(request, **kwargs)
  File "/home/airflow/.local/lib/python3.8/site-packages/requests/adapters.py", line 532, in send
    raise ReadTimeout(e, request=request)
requests.exceptions.ReadTimeout: HTTPSConnectionPool(host='data.sfgov.org', port=443): Read timed out. (read timeout=10)
[2024-02-04T09:58:34.311+0000] {taskinstance.py:1138} INFO - Marking task as FAILED. dag_id=sf_data_upload, task_id=sf311_extract_task, execution_date=20240204T095554, start_date=20240204T095823, end_date=20240204T095834
[2024-02-04T09:58:34.342+0000] {standard_task_runner.py:107} ERROR - Failed to execute job 61 for task sf311_extract_task (HTTPSConnectionPool(host='data.sfgov.org', port=443): Read timed out. (read timeout=10); 49)
[2024-02-04T09:58:34.443+0000] {local_task_job_runner.py:234} INFO - Task exited with return code 1
[2024-02-04T09:58:34.465+0000] {taskinstance.py:3280} INFO - 0 downstream tasks scheduled from follow-on schedule check
