[2024-02-04T09:56:14.387+0000] {taskinstance.py:1956} INFO - Dependencies all met for dep_context=non-requeueable deps ti=<TaskInstance: sf_data_upload.sf311_extract_task manual__2024-02-04T09:55:54.011497+00:00 [queued]>
[2024-02-04T09:56:14.396+0000] {taskinstance.py:1956} INFO - Dependencies all met for dep_context=requeueable deps ti=<TaskInstance: sf_data_upload.sf311_extract_task manual__2024-02-04T09:55:54.011497+00:00 [queued]>
[2024-02-04T09:56:14.398+0000] {taskinstance.py:2170} INFO - Starting attempt 2 of 2
[2024-02-04T09:56:14.407+0000] {taskinstance.py:2191} INFO - Executing <Task(PythonOperator): sf311_extract_task> on 2024-02-04 09:55:54.011497+00:00
[2024-02-04T09:56:14.412+0000] {standard_task_runner.py:60} INFO - Started process 99 to run task
[2024-02-04T09:56:14.416+0000] {standard_task_runner.py:87} INFO - Running: ['***', 'tasks', 'run', 'sf_data_upload', 'sf311_extract_task', 'manual__2024-02-04T09:55:54.011497+00:00', '--job-id', '57', '--raw', '--subdir', 'DAGS_FOLDER/sf311_data_upload_dag.py', '--cfg-path', '/tmp/tmpeuqqbh2q']
[2024-02-04T09:56:14.418+0000] {standard_task_runner.py:88} INFO - Job 57: Subtask sf311_extract_task
[2024-02-04T09:56:14.465+0000] {task_command.py:423} INFO - Running <TaskInstance: sf_data_upload.sf311_extract_task manual__2024-02-04T09:55:54.011497+00:00 [running]> on host 007dc6bfb309
[2024-02-04T09:56:14.511+0000] {taskinstance.py:2480} INFO - Exporting env vars: AIRFLOW_CTX_DAG_OWNER='***' AIRFLOW_CTX_DAG_ID='sf_data_upload' AIRFLOW_CTX_TASK_ID='sf311_extract_task' AIRFLOW_CTX_EXECUTION_DATE='2024-02-04T09:55:54.011497+00:00' AIRFLOW_CTX_TRY_NUMBER='2' AIRFLOW_CTX_DAG_RUN_ID='manual__2024-02-04T09:55:54.011497+00:00'
[2024-02-04T09:56:14.841+0000] {socrata.py:63} WARNING - Requests made without an app_token will be subject to strict throttling limits.
[2024-02-04T09:56:15.376+0000] {taskinstance.py:2698} ERROR - Task failed with exception
Traceback (most recent call last):
  File "/home/airflow/.local/lib/python3.8/site-packages/airflow/models/taskinstance.py", line 433, in _execute_task
    result = execute_callable(context=context, **execute_callable_kwargs)
  File "/home/airflow/.local/lib/python3.8/site-packages/airflow/operators/python.py", line 199, in execute
    return_value = self.execute_callable()
  File "/home/airflow/.local/lib/python3.8/site-packages/airflow/operators/python.py", line 216, in execute_callable
    return self.python_callable(*self.op_args, **self.op_kwargs)
  File "/opt/airflow/plugins/sf311_extract.py", line 34, in pull_opensf_data
    results = client.get(endpoint, limit = limit, offset = offset, where=filters)
  File "/home/airflow/.local/lib/python3.8/site-packages/sodapy/socrata.py", line 412, in get
    response = self._perform_request(
  File "/home/airflow/.local/lib/python3.8/site-packages/sodapy/socrata.py", line 555, in _perform_request
    utils.raise_for_status(response)
  File "/home/airflow/.local/lib/python3.8/site-packages/sodapy/utils.py", line 30, in raise_for_status
    raise requests.exceptions.HTTPError(http_error_msg, response=response)
requests.exceptions.HTTPError: 400 Client Error: Bad Request.
	Query coordinator error: query.soql.no-such-column; No such column: opened; position: Map(row -> 1, column -> 363, line -> "SELECT `service_request_id`, `requested_datetime`, `closed_date`, `updated_datetime`, `status_description`, `status_notes`, `agency_responsible`, `service_name`, `service_subtype`, `service_details`, `address`, `street`, `supervisor_district`, `neighborhoods_sffind_boundaries`, `police_district`, `lat`, `long`, `point`, `source`, `media_url`, `bos_2012` WHERE `opened` >= \"2024-01-30\" LIMIT 40000 OFFSET 0\n                                                                                                                                                                                                                                                                                                                                                                          ^")
[2024-02-04T09:56:15.402+0000] {taskinstance.py:1138} INFO - Marking task as FAILED. dag_id=sf_data_upload, task_id=sf311_extract_task, execution_date=20240204T095554, start_date=20240204T095614, end_date=20240204T095615
[2024-02-04T09:56:15.419+0000] {standard_task_runner.py:107} ERROR - Failed to execute job 57 for task sf311_extract_task (400 Client Error: Bad Request.
	Query coordinator error: query.soql.no-such-column; No such column: opened; position: Map(row -> 1, column -> 363, line -> "SELECT `service_request_id`, `requested_datetime`, `closed_date`, `updated_datetime`, `status_description`, `status_notes`, `agency_responsible`, `service_name`, `service_subtype`, `service_details`, `address`, `street`, `supervisor_district`, `neighborhoods_sffind_boundaries`, `police_district`, `lat`, `long`, `point`, `source`, `media_url`, `bos_2012` WHERE `opened` >= \"2024-01-30\" LIMIT 40000 OFFSET 0\n                                                                                                                                                                                                                                                                                                                                                                          ^"); 99)
[2024-02-04T09:56:15.469+0000] {local_task_job_runner.py:234} INFO - Task exited with return code 1
[2024-02-04T09:56:15.487+0000] {taskinstance.py:3280} INFO - 0 downstream tasks scheduled from follow-on schedule check
