[2024-02-03T23:18:19.268+0000] {taskinstance.py:1956} INFO - Dependencies all met for dep_context=non-requeueable deps ti=<TaskInstance: sf_data_upload.sf311_add_coord_task scheduled__2024-02-02T00:00:00+00:00 [queued]>
[2024-02-03T23:18:19.273+0000] {taskinstance.py:1956} INFO - Dependencies all met for dep_context=requeueable deps ti=<TaskInstance: sf_data_upload.sf311_add_coord_task scheduled__2024-02-02T00:00:00+00:00 [queued]>
[2024-02-03T23:18:19.274+0000] {taskinstance.py:2170} INFO - Starting attempt 1 of 1
[2024-02-03T23:18:19.281+0000] {taskinstance.py:2191} INFO - Executing <Task(PythonOperator): sf311_add_coord_task> on 2024-02-02 00:00:00+00:00
[2024-02-03T23:18:19.286+0000] {standard_task_runner.py:60} INFO - Started process 89 to run task
[2024-02-03T23:18:19.288+0000] {standard_task_runner.py:87} INFO - Running: ['***', 'tasks', 'run', 'sf_data_upload', 'sf311_add_coord_task', 'scheduled__2024-02-02T00:00:00+00:00', '--job-id', '26', '--raw', '--subdir', 'DAGS_FOLDER/sf311_data_upload_dag.py', '--cfg-path', '/tmp/tmpwb7wjklr']
[2024-02-03T23:18:19.291+0000] {standard_task_runner.py:88} INFO - Job 26: Subtask sf311_add_coord_task
[2024-02-03T23:18:19.325+0000] {task_command.py:423} INFO - Running <TaskInstance: sf_data_upload.sf311_add_coord_task scheduled__2024-02-02T00:00:00+00:00 [running]> on host f7935484a45e
[2024-02-03T23:18:19.405+0000] {taskinstance.py:2480} INFO - Exporting env vars: AIRFLOW_CTX_DAG_OWNER='***' AIRFLOW_CTX_DAG_ID='sf_data_upload' AIRFLOW_CTX_TASK_ID='sf311_add_coord_task' AIRFLOW_CTX_EXECUTION_DATE='2024-02-02T00:00:00+00:00' AIRFLOW_CTX_TRY_NUMBER='1' AIRFLOW_CTX_DAG_RUN_ID='scheduled__2024-02-02T00:00:00+00:00'
[2024-02-03T23:18:23.337+0000] {connectionpool.py:824} WARNING - Retrying (Retry(total=1, connect=None, read=None, redirect=None, status=None)) after connection broken by 'ReadTimeoutError("HTTPSConnectionPool(host='nominatim.openstreetmap.org', port=443): Read timed out. (read timeout=1)")': /search?q=301+ITALY+AVE%2C+SAN+FRANCISCO%2C+CA%2C+94112+%28Virtual%29&format=json&limit=1
[2024-02-03T23:18:51.525+0000] {connectionpool.py:824} WARNING - Retrying (Retry(total=1, connect=None, read=None, redirect=None, status=None)) after connection broken by 'ReadTimeoutError("HTTPSConnectionPool(host='nominatim.openstreetmap.org', port=443): Read timed out. (read timeout=1)")': /search?q=14+CLEMENT+ST%2C+SAN+FRANCISCO%2C+CA%2C+94118&format=json&limit=1
[2024-02-03T23:19:06.529+0000] {connectionpool.py:824} WARNING - Retrying (Retry(total=1, connect=None, read=None, redirect=None, status=None)) after connection broken by 'ReadTimeoutError("HTTPSConnectionPool(host='nominatim.openstreetmap.org', port=443): Read timed out. (read timeout=1)")': /search?q=133+BUCHANAN+ST%2C+SAN+FRANCISCO%2C+CA%2C+94102&format=json&limit=1
[2024-02-03T23:19:10.975+0000] {connectionpool.py:824} WARNING - Retrying (Retry(total=1, connect=None, read=None, redirect=None, status=None)) after connection broken by 'ReadTimeoutError("HTTPSConnectionPool(host='nominatim.openstreetmap.org', port=443): Read timed out. (read timeout=1)")': /search?q=330+BYXBEE+ST%2C+SAN+FRANCISCO%2C+CA%2C+94132&format=json&limit=1
[2024-02-03T23:19:24.604+0000] {connectionpool.py:824} WARNING - Retrying (Retry(total=1, connect=None, read=None, redirect=None, status=None)) after connection broken by 'ReadTimeoutError("HTTPSConnectionPool(host='nominatim.openstreetmap.org', port=443): Read timed out. (read timeout=1)")': /search?q=1442+BROADWAY%2C+SAN+FRANCISCO%2C+CA%2C+94110&format=json&limit=1
[2024-02-03T23:19:41.715+0000] {taskinstance.py:2698} ERROR - Task failed with exception
Traceback (most recent call last):
  File "/home/airflow/.local/lib/python3.8/site-packages/airflow/models/taskinstance.py", line 433, in _execute_task
    result = execute_callable(context=context, **execute_callable_kwargs)
  File "/home/airflow/.local/lib/python3.8/site-packages/airflow/operators/python.py", line 199, in execute
    return_value = self.execute_callable()
  File "/home/airflow/.local/lib/python3.8/site-packages/airflow/operators/python.py", line 216, in execute_callable
    return self.python_callable(*self.op_args, **self.op_kwargs)
  File "/opt/airflow/plugins/sf311_preprocess_2.py", line 45, in address_to_coordinates
    results_df = pd.DataFrame({'service_request_id': new_service, 'lat': new_lat, 'long': new_long})
NameError: name 'pd' is not defined
[2024-02-03T23:19:41.748+0000] {taskinstance.py:1138} INFO - Marking task as FAILED. dag_id=sf_data_upload, task_id=sf311_add_coord_task, execution_date=20240202T000000, start_date=20240203T231819, end_date=20240203T231941
[2024-02-03T23:19:41.762+0000] {standard_task_runner.py:107} ERROR - Failed to execute job 26 for task sf311_add_coord_task (name 'pd' is not defined; 89)
[2024-02-03T23:19:41.792+0000] {local_task_job_runner.py:234} INFO - Task exited with return code 1
[2024-02-03T23:19:41.813+0000] {taskinstance.py:3280} INFO - 0 downstream tasks scheduled from follow-on schedule check
