[2024-02-03T23:28:58.198+0000] {taskinstance.py:1956} INFO - Dependencies all met for dep_context=non-requeueable deps ti=<TaskInstance: sf_data_upload.sf311_add_coord_task scheduled__2024-02-02T00:00:00+00:00 [queued]>
[2024-02-03T23:28:58.204+0000] {taskinstance.py:1956} INFO - Dependencies all met for dep_context=requeueable deps ti=<TaskInstance: sf_data_upload.sf311_add_coord_task scheduled__2024-02-02T00:00:00+00:00 [queued]>
[2024-02-03T23:28:58.206+0000] {taskinstance.py:2170} INFO - Starting attempt 2 of 2
[2024-02-03T23:28:58.228+0000] {taskinstance.py:2191} INFO - Executing <Task(PythonOperator): sf311_add_coord_task> on 2024-02-02 00:00:00+00:00
[2024-02-03T23:28:58.234+0000] {standard_task_runner.py:60} INFO - Started process 58 to run task
[2024-02-03T23:28:58.236+0000] {standard_task_runner.py:87} INFO - Running: ['***', 'tasks', 'run', 'sf_data_upload', 'sf311_add_coord_task', 'scheduled__2024-02-02T00:00:00+00:00', '--job-id', '31', '--raw', '--subdir', 'DAGS_FOLDER/sf311_data_upload_dag.py', '--cfg-path', '/tmp/tmph768hn2h']
[2024-02-03T23:28:58.239+0000] {standard_task_runner.py:88} INFO - Job 31: Subtask sf311_add_coord_task
[2024-02-03T23:28:58.282+0000] {task_command.py:423} INFO - Running <TaskInstance: sf_data_upload.sf311_add_coord_task scheduled__2024-02-02T00:00:00+00:00 [running]> on host b64dc55eb6ec
[2024-02-03T23:28:58.372+0000] {taskinstance.py:2480} INFO - Exporting env vars: AIRFLOW_CTX_DAG_OWNER='***' AIRFLOW_CTX_DAG_ID='sf_data_upload' AIRFLOW_CTX_TASK_ID='sf311_add_coord_task' AIRFLOW_CTX_EXECUTION_DATE='2024-02-02T00:00:00+00:00' AIRFLOW_CTX_TRY_NUMBER='2' AIRFLOW_CTX_DAG_RUN_ID='scheduled__2024-02-02T00:00:00+00:00'
[2024-02-03T23:29:08.249+0000] {connectionpool.py:824} WARNING - Retrying (Retry(total=1, connect=None, read=None, redirect=None, status=None)) after connection broken by 'ReadTimeoutError("HTTPSConnectionPool(host='nominatim.openstreetmap.org', port=443): Read timed out. (read timeout=1)")': /search?q=1400+ARMSTRONG+AVE%2C+SAN+FRANCISCO%2C+CA%2C+94124+%28Virtual%29&format=json&limit=1
[2024-02-03T23:29:27.888+0000] {connectionpool.py:824} WARNING - Retrying (Retry(total=1, connect=None, read=None, redirect=None, status=None)) after connection broken by 'ReadTimeoutError("HTTPSConnectionPool(host='nominatim.openstreetmap.org', port=443): Read timed out. (read timeout=1)")': /search?q=1890+CLAY+ST%2C+SAN+FRANCISCO%2C+CA%2C+94109&format=json&limit=1
[2024-02-03T23:29:50.722+0000] {connectionpool.py:824} WARNING - Retrying (Retry(total=1, connect=None, read=None, redirect=None, status=None)) after connection broken by 'ReadTimeoutError("HTTPSConnectionPool(host='nominatim.openstreetmap.org', port=443): Read timed out. (read timeout=1)")': /search?q=900+VAN+NESS+AVE%2C+SAN+FRANCISCO%2C+CA%2C+94109&format=json&limit=1
[2024-02-03T23:30:01.948+0000] {connectionpool.py:824} WARNING - Retrying (Retry(total=1, connect=None, read=None, redirect=None, status=None)) after connection broken by 'ReadTimeoutError("HTTPSConnectionPool(host='nominatim.openstreetmap.org', port=443): Read timed out. (read timeout=1)")': /search?q=111+CHESTNUT+ST%2C+SAN+FRANCISCO%2C+CA%2C+94133&format=json&limit=1
[2024-02-03T23:30:03.070+0000] {connectionpool.py:824} WARNING - Retrying (Retry(total=0, connect=None, read=None, redirect=None, status=None)) after connection broken by 'ReadTimeoutError("HTTPSConnectionPool(host='nominatim.openstreetmap.org', port=443): Read timed out. (read timeout=1)")': /search?q=111+CHESTNUT+ST%2C+SAN+FRANCISCO%2C+CA%2C+94133&format=json&limit=1
[2024-02-03T23:30:04.201+0000] {logging_mixin.py:188} INFO - Error geocoding address '111 CHESTNUT ST, SAN FRANCISCO, CA, 94133': HTTPSConnectionPool(host='nominatim.openstreetmap.org', port=443): Max retries exceeded with url: /search?q=111+CHESTNUT+ST%2C+SAN+FRANCISCO%2C+CA%2C+94133&format=json&limit=1 (Caused by ReadTimeoutError("HTTPSConnectionPool(host='nominatim.openstreetmap.org', port=443): Read timed out. (read timeout=1)"))
[2024-02-03T23:30:05.353+0000] {connectionpool.py:824} WARNING - Retrying (Retry(total=1, connect=None, read=None, redirect=None, status=None)) after connection broken by 'ReadTimeoutError("HTTPSConnectionPool(host='nominatim.openstreetmap.org', port=443): Read timed out. (read timeout=1)")': /search?q=1239+REVERE+AVE%2C+SAN+FRANCISCO%2C+CA%2C+94124&format=json&limit=1
[2024-02-03T23:30:06.501+0000] {connectionpool.py:824} WARNING - Retrying (Retry(total=0, connect=None, read=None, redirect=None, status=None)) after connection broken by 'ReadTimeoutError("HTTPSConnectionPool(host='nominatim.openstreetmap.org', port=443): Read timed out. (read timeout=1)")': /search?q=1239+REVERE+AVE%2C+SAN+FRANCISCO%2C+CA%2C+94124&format=json&limit=1
[2024-02-03T23:30:12.521+0000] {connectionpool.py:824} WARNING - Retrying (Retry(total=1, connect=None, read=None, redirect=None, status=None)) after connection broken by 'ReadTimeoutError("HTTPSConnectionPool(host='nominatim.openstreetmap.org', port=443): Read timed out. (read timeout=1)")': /search?q=1245+GIRARD+ST%2C+SAN+FRANCISCO%2C+CA%2C+94134+%28Virtual%29&format=json&limit=1
[2024-02-03T23:30:25.430+0000] {taskinstance.py:2698} ERROR - Task failed with exception
Traceback (most recent call last):
  File "/home/airflow/.local/lib/python3.8/site-packages/airflow/models/taskinstance.py", line 433, in _execute_task
    result = execute_callable(context=context, **execute_callable_kwargs)
  File "/home/airflow/.local/lib/python3.8/site-packages/airflow/operators/python.py", line 199, in execute
    return_value = self.execute_callable()
  File "/home/airflow/.local/lib/python3.8/site-packages/airflow/operators/python.py", line 216, in execute_callable
    return self.python_callable(*self.op_args, **self.op_kwargs)
  File "/opt/airflow/plugins/sf311_preprocess_2.py", line 45, in address_to_coordinates
    results_df = pd.DataFrame({'service_request_id': new_service, 'lat': new_lat, 'long': new_long})
NameError: name 'pd' is not defined
[2024-02-03T23:30:25.474+0000] {taskinstance.py:1138} INFO - Marking task as FAILED. dag_id=sf_data_upload, task_id=sf311_add_coord_task, execution_date=20240202T000000, start_date=20240203T232858, end_date=20240203T233025
[2024-02-03T23:30:25.491+0000] {standard_task_runner.py:107} ERROR - Failed to execute job 31 for task sf311_add_coord_task (name 'pd' is not defined; 58)
[2024-02-03T23:30:25.557+0000] {local_task_job_runner.py:234} INFO - Task exited with return code 1
[2024-02-03T23:30:25.575+0000] {taskinstance.py:3280} INFO - 0 downstream tasks scheduled from follow-on schedule check
